Workbook

Sheet README - Assumptions
A1: NorthPeak Distribution Co. - Sales Performance Analysis
A2: Portfolio dataset: FY2025 sales, generated with realistic, formula-linked business logic.
A4: Business Scenario
A5: • | B5: NorthPeak Distribution Co. is a mid-market B2B/B2C distributor of technology and office solutions operating across four US regions, selling through Online, Retail Partner, and Direct Sales channels to Consumer, SMB, and Enterprise customers.
A7: Scope
A8: • | B8: Sales_Data contains 1,200 orders covering all 12 months of 2025, with unique Order IDs formatted ORD-2025-00001 through ORD-2025-01200.
A9: • | B9: Products contains 20 SKUs across 4 categories (Electronics, Accessories, Office Equipment, Software), each with a Standard Price used as the pricing basis.
A10: • | B10: Monthly_Targets contains 12 rows (Jan-Dec 2025); Sales is a live formula that sums actual order-level Sales from Sales_Data for that month, so it updates automatically if the underlying data changes. Sales Target is a manually set planning figure for comparison.
A12: Pricing & Discount Logic
A13: • | B13: Unit Price = Product Standard Price adjusted by small order-level variance (+/-4%) and a channel effect (Online 1.00x, Retail Partner 0.97x, Direct Sales 0.98x, reflecting wholesale/negotiated pricing).
A14: • | B14: Discount % varies by Customer Segment: Consumer 0-8%, SMB 5-15%, Enterprise 10-25%, with a small channel adjustment (Direct Sales +2%, Online -1%), reflecting that larger buyers negotiate harder.
A15: • | B15: Units per order scale with segment: Consumer 1-3, SMB 3-10, Enterprise 8-40.
A17: Cost & Profitability Logic
A18: • | B18: Cost is driven by category-specific gross-margin structure, expressed as a cost ratio applied to each order's Sales value (Cost = Sales x Cost Ratio): Software ~20-28% (high-margin, digital), Accessories ~55-62%, Office Equipment ~60-68%, Electronics ~68-74% (thin-margin, hardware-heavy). Each order's ratio includes small realistic variance around these category bases.
A19: • | B19: Profit = Sales - Cost, calculated per order and aggregable across any dimension.
A21: Seasonality
A22: • | B22: Order volume follows a realistic seasonal curve: slow start in Jan-Feb, steady growth through mid-year, a back-to-office/school bump in Aug-Sep, and the strongest volume in Nov-Dec (holiday demand).
A23: • | B23: Monthly Sales Targets were set as a smoothed version of realistic monthly plan figures and intentionally do not perfectly track actuals - some months beat target, some miss it, as in a real business.
A25: Formula Integrity
A26: • | B26: Sales_Data: Sales = Units x Unit Price x (1 - Discount %); Cost = Sales x order-level Cost Ratio (rounded); Profit = Sales - Cost. All three are live formulas, not hardcoded values.
A27: • | B27: Monthly_Targets: Sales is a SUMPRODUCT formula that filters Sales_Data by year and month and sums the Sales column - it will recalculate automatically if any order in Sales_Data is added, changed, or removed.
A29: Intended Use
A30: • | B30: This workbook is designed to support Excel PivotTable/dashboard analysis, SQL practice (import Sales_Data, Products, Monthly_Targets as relational tables), and Power BI modeling (Sales_Data as fact table, Products and Monthly_Targets as dimension/reference tables).

Sheet Sales_Data
A1: Order ID | B1: Order Date | C1: Region | D1: Category | E1: Product | F1: Customer Segment | G1: Sales Channel | H1: Salesperson | I1: Units | J1: Unit Price | K1: Discount % | L1: Sales | M1: Cost | N1: Profit
A2: ORD-2025-00001 | B2: 45658 | C2: Northeast | D2: Office Equipment | E2: Standing Desk | F2: Enterprise | G2: Direct Sales | H2: Daniel Brooks | I2: 37 | J2: 397.5 | K2: 0.1751 | L2: =I2*J2*(1-K2) -> 12132.217 | M2: =ROUND(L2*0.654,2) -> 7934.47 | N2: =L2-M2 -> 4197.7467
A3: ORD-2025-00002 | B3: 45658 | C3: Southeast | D3: Office Equipment | E3: Laser Printer | F3: Consumer | G3: Retail Partner | H3: Maria Gonzalez | I3: 1 | J3: 240.85 | K3: 0.0813 | L3: =I3*J3*(1-K3) -> 221.26889 | M3: =ROUND(L3*0.6321,2) -> 139.86 | N3: =L3-M3 -> 81.408895
A4: ORD-2025-00003 | B4: 45659 | C4: West | D4: Electronics | E4: Laptop Pro 14 | F4: Consumer | G4: Online | H4: Online Store - West | I4: 1 | J4: 1252.95 | K4: 0.0438 | L4: =I4*J4*(1-K4) -> 1198.0708 | M4: =ROUND(L4*0.7311,2) -> 875.91 | N4: =L4-M4 -> 322.16079
A5: ORD-2025-00004 | B5: 45660 | C5: Northeast | D5: Electronics | E5: Tablet Pro 11 | F5: SMB | G5: Retail Partner | H5: Emily Carter | I5: 6 | J5: 682.31 | K5: 0.1011 | L5: =I5*J5*(1-K5) -> 3679.9708 | M5: =ROUND(L5*0.6849,2) -> 2520.41 | N5: =L5-M5 -> 1159.5608
A6: ORD-2025-00005 | B6: 45660 | C6: Northeast | D6: Office Equipment | E6: All-in-One Printer | F6: Enterprise | G6: Direct Sales | H6: Emily Carter | I6: 39 | J6: 190.56 | K6: 0.1979 | L6: =I6*J6*(1-K6) -> 5961.0789 | M6: =ROUND(L6*0.6661,2) -> 3970.67 | N6: =L6-M6 -> 1990.4089
A7: ORD-2025-00006 | B7: 45662 | C7: West | D7: Electronics | E7: Laptop Pro 14 | F7: Consumer | G7: Retail Partner | H7: Sophia Martinez | I7: 2 | J7: 1231.69 | K7: 0.0412 | L7: =I7*J7*(1-K7) -> 2361.8887 | M7: =ROUND(L7*0.7218,2) -> 1704.81 | N7: =L7-M7 -> 657.07874
A8: ORD-2025-00007 | B8: 45662 | C8: Northeast | D8: Accessories | E8: Mechanical Keyboard | F8: Consumer | G8: Retail Partner | H8: Emily Carter | I8: 3 | J8: 83.98 | K8: 0.0744 | L8: =I8*J8*(1-K8) -> 233.19566 | M8: =ROUND(L8*0.5858,2) -> 136.61 | N8: =L8-M8 -> 96.585664
A9: ORD-2025-00008 | B9: 45663 | C9: West | D9: Software | E9: Productivity Suite License | F9: Consumer | G9: Retail Partner | H9: Rachel Adams | I9: 1 | J9: 146.66 | K9: 0.0427 | L9: =I9*J9*(1-K9) -> 140.39762 | M9: =ROUND(L9*0.2566,2) -> 36.03 | N9: =L9-M9 -> 104.36762
A10: ORD-2025-00009 | B10: 45664 | C10: Southeast | D10: Accessories | E10: Wireless Mouse | F10: Consumer | G10: Online | H10: Online Store - Southeast | I10: 2 | J10: 38.22 | K10: 0.0032 | L10: =I10*J10*(1-K10) -> 76.195392 | M10: =ROUND(L10*0.5766,2) -> 43.93 | N10: =L10-M10 -> 32.265392
A11: ORD-2025-00010 | B11: 45664 | C11: Midwest | D11: Accessories | E11: Wireless Headset | F11: Consumer | G11: Online | H11: Online Store - Midwest | I11: 3 | J11: 97.53 | K11: 0.0296 | L11: =I11*J11*(1-K11) -> 283.92934 | M11: =ROUND(L11*0.5932,2) -> 168.43 | N11: =L11-M11 -> 115.49934
A12: ORD-2025-00011 | B12: 45664 | C12: Midwest | D12: Office Equipment | E12: All-in-One Printer | F12: Consumer | G12: Online | H12: Online Store - Midwest | I12: 1 | J12: 194.33 | K12: 0.0556 | L12: =I12*J12*(1-K12) -> 183.52525 | M12: =ROUND(L12*0.6643,2) -> 121.92 | N12: =L12-M12 -> 61.605252
A13: ORD-2025-00012 | B13: 45665 | C13: West | D13: Electronics | E13: Ultrabook Air 13 | F13: Enterprise | G13: Direct Sales | H13: Sophia Martinez | I13: 25 | J13: 1073.01 | K13: 0.2493 | L13: =I13*J13*(1-K13) -> 20137.715 | M13: =ROUND(L13*0.6898,2) -> 13891 | N13: =L13-M13 -> 6246.7152
A14: ORD-2025-00013 | B14: 45665 | C14: West | D14: Electronics | E14: Laptop Pro 14 | F14: Enterprise | G14: Direct Sales | H14: Kevin O'Brien | I14: 20 | J14: 1295.26 | K14: 0.1531 | L14: =I14*J14*(1-K14) -> 21939.114 | M14: =ROUND(L14*0.704,2) -> 15445.14 | N14: =L14-M14 -> 6493.9739
A15: ORD-2025-00014 | B15: 45665 | C15: Southeast | D15: Office Equipment | E15: Laser Printer | F15: Enterprise | G15: Direct Sales | H15: Maria Gonzalez | I15: 28 | J15: 238.41 | K15: 0.1433 | L15: =I15*J15*(1-K15) -> 5718.8837 | M15: =ROUND(L15*0.6631,2) -> 3792.19 | N15: =L15-M15 -> 1926.6937
A16: ORD-2025-00015 | B16: 45665 | C16: Midwest | D16: Software | E16: Productivity Suite License | F16: Consumer | G16: Online | H16: Online Store - Midwest | I16: 1 | J16: 143.13 | K16: 0.0436 | L16: =I16*J16*(1-K16) -> 136.88953 | M16: =ROUND(L16*0.2135,2) -> 29.23 | N16: =L16-M16 -> 107.65953
A17: ORD-2025-00016 | B17: 45666 | C17: Southeast | D17: Electronics | E17: Business Desktop Tower | F17: SMB | G17: Online | H17: Online Store - Southeast | I17: 10 | J17: 879.04 | K17: 0.0627 | L17: =I17*J17*(1-K17) -> 8239.2419 | M17: =ROUND(L17*0.7076,2) -> 5830.09 | N17: =L17-M17 -> 2409.1519
A18: ORD-2025-00017 | B18: 45666 | C18: West | D18: Electronics | E18: Business Desktop Tower | F18: Consumer | G18: Retail Partner | H18: Sophia Martinez | I18: 3 | J18: 866.7 | K18: 0.0704 | L18: =I18*J18*(1-K18) -> 2417.053 | M18: =ROUND(L18*0.6802,2) -> 1644.08 | N18: =L18-M18 -> 772.97296
A19: ORD-2025-00018 | B19: 45666 | C19: Southeast | D19: Electronics | E19: Business Desktop Tower | F19: Enterprise | G19: Direct Sales | H19: Maria Gonzalez | I19: 27 | J19: 905.1 | K19: 0.1692 | L19: =I19*J19*(1-K19) -> 20302.841 | M19: =ROUND(L19*0.6919,2) -> 14047.54 | N19: =L19-M19 -> 6255.3012
A20: ORD-2025-00019 | B20: 45667 | C20: West | D20: Office Equipment | E20: Paper Shredder | F20: Consumer | G20: Online | H20: Online Store - West | I20: 1 | J20: 125.4 | K20: 0.0326 | L20: =I20*J20*(1-K20) -> 121.31196 | M20: =ROUND(L20*0.6192,2) -> 75.12 | N20: =L20-M20 -> 46.19196
A21: ORD-2025-00020 | B21: 45667 | C21: Northeast | D21: Electronics | E21: Business Desktop Tower | F21: Enterprise | G21: Direct Sales | H21: Emily Carter | I21: 29 | J21: 865.42 | K21: 0.1992 | L21: =I21*J21*(1-K21) -> 20097.822 | M21: =ROUND(L21*0.7264,2) -> 14599.06 | N21: =L21-M21 -> 5498.7617
A22: ORD-2025-00021 | B22: 45667 | C22: West | D22: Office Equipment | E22: All-in-One Printer | F22: Enterprise | G22: Retail Partner | H22: Sophia Martinez | I22: 14 | J22: 186.44 | K22: 0.1189 | L22: =I22*J22*(1-K22) -> 2299.812 | M22: =ROUND(L22*0.6259,2) -> 1439.45 | N22: =L22-M22 -> 860.36198
A23: ORD-2025-00022 | B23: 45667 | C23: Southeast | D23: Software | E23: Productivity Suite License | F23: SMB | G23: Retail Partner | H23: James Whitfield | I23: 5 | J23: 140.97 | K23: 0.0864 | L23: =I23*J23*(1-K23) -> 643.95096 | M23: =ROUND(L23*0.2327,2) -> 149.85 | N23: =L23-M23 -> 494.10096
A24: ORD-2025-00023 | B24: 45668 | C24: Northeast | D24: Electronics | E24: Laptop Pro 14 | F24: SMB | G24: Retail Partner | H24: Daniel Brooks | I24: 5 | J24: 1276.04 | K24: 0.127 | L24: =I24*J24*(1-K24) -> 5569.9146 | M24: =ROUND(L24*0.7198,2) -> 4009.22 | N24: =L24-M24 -> 1560.6946
A25: ORD-2025-00024 | B25: 45669 | C25: West | D25: Accessories | E25: Laptop Sleeve 14-inch | F25: Consumer | G25: Retail Partner | H25: Rachel Adams | I25: 1 | J25: 27.26 | K25: 0.0056 | L25: =I25*J25*(1-K25) -> 27.107344 | M25: =ROUND(L25*0.5607,2) -> 15.2 | N25: =L25-M25 -> 11.907344
A26: ORD-2025-00025 | B26: 45669 | C26: Southeast | D26: Accessories | E26: Mechanical Keyboard | F26: Enterprise | G26: Direct Sales | H26: Maria Gonzalez | I26: 13 | J26: 84.33 | K26: 0.1931 | L26: =I26*J26*(1-K26) -> 884.5964 | M26: =ROUND(L26*0.5542,2) -> 490.24 | N26: =L26-M26 -> 394.3564
A27: ORD-2025-00026 | B27: 45669 | C27: West | D27: Office Equipment | E27: Laser Printer | F27: Consumer | G27: Online | H27: Online Store - West | I27: 1 | J27: 251.17 | K27: 0.0221 | L27: =I27*J27*(1-K27) -> 245.61914 | M27: =ROUND(L27*0.6537,2) -> 160.56 | N27: =L27-M27 -> 85.059143
A28: ORD-2025-00027 | B28: 45669 | C28: West | D28: Accessories | E28: Wireless Mouse | F28: Enterprise | G28: Direct Sales | H28: Rachel Adams | I28: 8 | J28: 38.52 | K28: 0.2415 | L28: =I28*J28*(1-K28) -> 233.73936 | M28: =ROUND(L28*0.5567,2) -> 130.12 | N28: =L28-M28 -> 103.61936
A29: ORD-2025-00028 | B29: 45670 | C29: Midwest | D29: Electronics | E29: Ultrabook Air 13 | F29: Enterprise | G29: Online | H29: Online Store - Midwest | I29: 8 | J29: 1114.85 | K29: 0.101 | L29: =I29*J29*(1-K29) -> 8018.0012 | M29: =ROUND(L29*0.7331,2) -> 5878 | N29: =L29-M29 -> 2140.0012
A30: ORD-2025-00029 | B30: 45670 | C30: Northeast | D30: Office Equipment | E30: Paper Shredder | F30: SMB | G30: Direct Sales | H30: Daniel Brooks | I30: 10 | J30: 124.25 | K30: 0.0829 | L30: =I30*J30*(1-K30) -> 1139.4968 | M30: =ROUND(L30*0.6538,2) -> 745 | N30: =L30-M30 -> 394.49675
A31: ORD-2025-00030 | B31: 45671 | C31: West | D31: Electronics | E31: 27-inch 4K Monitor | F31: Consumer | G31: Online | H31: Online Store - West | I31: 1 | J31: 456.12 | K31: 0.0352 | L31: =I31*J31*(1-K31) -> 440.06458 | M31: =ROUND(L31*0.6893,2) -> 303.34 | N31: =L31-M31 -> 136.72458
A32: ORD-2025-00031 | B32: 45671 | C32: Northeast | D32: Software | E32: Antivirus Security License | F32: Consumer | G32: Online | H32: Online Store - Northeast | I32: 1 | J32: 59.29 | K32: 0.0251 | L32: =I32*J32*(1-K32) -> 57.801821 | M32: =ROUND(L32*0.2521,2) -> 14.57 | N32: =L32-M32 -> 43.231821
A33: ORD-2025-00032 | B33: 45672 | C33: Midwest | D33: Office Equipment | E33: Standing Desk | F33: SMB | G33: Direct Sales | H33: Robert Chen | I33: 9 | J33: 398.16 | K33: 0.1534 | L33: =I33*J33*(1-K33) -> 3033.7403 | M33: =ROUND(L33*0.6166,2) -> 1870.6 | N33: =L33-M33 -> 1163.1403
A34: ORD-2025-00033 | B34: 45672 | C34: Southeast | D34: Office Equipment | E34: Paper Shredder | F34: SMB | G34: Online | H34: Online Store - Southeast | I34: 9 | J34: 126.44 | K34: 0.0592 | L34: =I34*J34*(1-K34) -> 1070.5928 | M34: =ROUND(L34*0.6112,2) -> 654.35 | N34: =L34-M34 -> 416.24277
A35: ORD-2025-00034 | B35: 45672 | C35: West | D35: Software | E35: Accounting Software License | F35: Consumer | G35: Online | H35: Online Store - West | I35: 1 | J35: 255 | K35: 0.0466 | L35: =I35*J35*(1-K35) -> 243.117 | M35: =ROUND(L35*0.2693,2) -> 65.47 | N35: =L35-M35 -> 177.647
A36: ORD-2025-00035 | B36: 45675 | C36: Northeast | D36: Office Equipment | E36: Laser Printer | F36: Enterprise | G36: Online | H36: Online Store - Northeast | I36: 10 | J36: 254.06 | K36: 0.0972 | L36: =I36*J36*(1-K36) -> 2293.6537 | M36: =ROUND(L36*0.622,2) -> 1426.65 | N36: =L36-M36 -> 867.00368
A37: ORD-2025-00036 | B37: 45675 | C37: West | D37: Accessories | E37: Wireless Mouse | F37: Enterprise | G37: Direct Sales | H37: Kevin O'Brien | I37: 31 | J37: 38.03 | K37: 0.1972 | L37: =I37*J37*(1-K37) -> 946.445 | M37: =ROUND(L37*0.5573,2) -> 527.45 | N37: =L37-M37 -> 418.995
A38: ORD-2025-00037 | B38: 45675 | C38: Northeast | D38: Software | E38: Productivity Suite License | F38: SMB | G38: Online | H38: Online Store - Northeast | I38: 8 | J38: 149.92 | K38: 0.0574 | L38: =I38*J38*(1-K38) -> 1130.5167 | M38: =ROUND(L38*0.2127,2) -> 240.46 | N38: =L38-M38 -> 890.05674
A39: ORD-2025-00038 | B39: 45676 | C39: Midwest | D39: Accessories | E39: Laptop Sleeve 14-inch | F39: Consumer | G39: Retail Partner | H39: Robert Chen | I39: 2 | J39: 27.41 | K39: 0.0261 | L39: =I39*J39*(1-K39) -> 53.389198 | M39: =ROUND(L39*0.5696,2) -> 30.41 | N39: =L39-M39 -> 22.979198
A40: ORD-2025-00039 | B40: 45676 | C40: Southeast | D40: Software | E40: Project Management License | F40: Consumer | G40: Retail Partner | H40: James Whitfield | I40: 1 | J40: 186.81 | K40: 0.0969 | L40: =I40*J40*(1-K40) -> 168.70811 | M40: =ROUND(L40*0.2354,2) -> 39.71 | N40: =L40-M40 -> 128.99811
...

Sheet Products
A1: Product | B1: Category | C1: Standard Price
A2: Laptop Pro 14 | B2: Electronics | C2: 1299
A3: Ultrabook Air 13 | B3: Electronics | C3: 1099
A4: Business Desktop Tower | B4: Electronics | C4: 899
A5: 27-inch 4K Monitor | B5: Electronics | C5: 449
A6: Tablet Pro 11 | B6: Electronics | C6: 699
A7: Wireless Mouse | B7: Accessories | C7: 39
A8: Mechanical Keyboard | B8: Accessories | C8: 89
A9: USB-C Docking Station | B9: Accessories | C9: 159
A10: Laptop Sleeve 14-inch | B10: Accessories | C10: 29
A11: Wireless Headset | B11: Accessories | C11: 99
A12: Laser Printer | B12: Office Equipment | C12: 249
A13: All-in-One Printer | B13: Office Equipment | C13: 199
... A21: Accounting Software License | B21: Software | C21: 249

Sheet Monthly_Targets
A1: Month | B1: Sales | C1: Sales Target | E1: Variance vs Target %
A2: January | B2: =SUMPRODUCT((YEAR(Sales_Data!$B$2:$B$1201)=2025)*(MONTH(Sales_Data!$B$2:$B$1201)=ROW()-1)*Sales_Data!$L$2:$L$1201) -> 249219.22 | C2: 239300 | E2: =(B2-C2)/C2 -> 0.04145099
A3: February | B3: =SUMPRODUCT((YEAR(Sales_Data!$B$2:$B$1201)=2025)*(MONTH(Sales_Data!$B$2:$B$1201)=ROW()-1)*Sales_Data!$L$2:$L$1201) -> 173602.68 | C3: 158300 | E3: =(B3-C3)/C3 -> 0.09666884
A4: March | B4: =SUMPRODUCT((YEAR(Sales_Data!$B$2:$B$1201)=2025)*(MONTH(Sales_Data!$B$2:$B$1201)=ROW()-1)*Sales_Data!$L$2:$L$1201) -> 229353.72 | C4: 234700 | E4: =(B4-C4)/C4 -> -0.022779218
A5: April | B5: =SUMPRODUCT((YEAR(Sales_Data!$B$2:$B$1201)=2025)*(MONTH(Sales_Data!$B$2:$B$1201)=ROW()-1)*Sales_Data!$L$2:$L$1201) -> 229100.73 | C5: 208000 | E5: =(B5-C5)/C5 -> 0.10144581
A6: May | B6: =SUMPRODUCT((YEAR(Sales_Data!$B$2:$B$1201)=2025)*(MONTH(Sales_Data!$B$2:$B$1201)=ROW()-1)*Sales_Data!$L$2:$L$1201) -> 242858.01 | C6: 239700 | E6: =(B6-C6)/C6 -> 0.013174835
A7: June | B7: =SUMPRODUCT((YEAR(Sales_Data!$B$2:$B$1201)=2025)*(MONTH(Sales_Data!$B$2:$B$1201)=ROW()-1)*Sales_Data!$L$2:$L$1201) -> 205923.87 | C7: 193900 | E7: =(B7-C7)/C7 -> 0.062010669
A8: July | B8: =SUMPRODUCT((YEAR(Sales_Data!$B$2:$B$1201)=2025)*(MONTH(Sales_Data!$B$2:$B$1201)=ROW()-1)*Sales_Data!$L$2:$L$1201) -> 219914.48 | C8: 194900 | E8: =(B8-C8)/C8 -> 0.12834521
A9: August | B9: =SUMPRODUCT((YEAR(Sales_Data!$B$2:$B$1201)=2025)*(MONTH(Sales_Data!$B$2:$B$1201)=ROW()-1)*Sales_Data!$L$2:$L$1201) -> 287238.09 | C9: 284300 | E9: =(B9-C9)/C9 -> 0.010334484
A10: September | B10: =SUMPRODUCT((YEAR(Sales_Data!$B$2:$B$1201)=2025)*(MONTH(Sales_Data!$B$2:$B$1201)=ROW()-1)*Sales_Data!$L$2:$L$1201) -> 304839.51 | C10: 267400 | E10: =(B10-C10)/C10 -> 0.14001313
A11: October | B11: =SUMPRODUCT((YEAR(Sales_Data!$B$2:$B$1201)=2025)*(MONTH(Sales_Data!$B$2:$B$1201)=ROW()-1)*Sales_Data!$L$2:$L$1201) -> 224738.54 | C11: 219900 | E11: =(B11-C11)/C11 -> 0.022003362
A12: November | B12: =SUMPRODUCT((YEAR(Sales_Data!$B$2:$B$1201)=2025)*(MONTH(Sales_Data!$B$2:$B$1201)=ROW()-1)*Sales_Data!$L$2:$L$1201) -> 343748.28 | C12: 300600 | E12: =(B12-C12)/C12 -> 0.1435405
A13: December | B13: =SUMPRODUCT((YEAR(Sales_Data!$B$2:$B$1201)=2025)*(MONTH(Sales_Data!$B$2:$B$1201)=ROW()-1)*Sales_Data!$L$2:$L$1201) -> 355963.59 | C13: 321700 | E13: =(B13-C13)/C13 -> 0.10650788
